<?xml version="1.0" encoding="utf-8"?>
<robot name="e0509">

   <material name="black">
      <color rgba="0.0 0.0 0.0 1.0"/>
   </material>
   <material name="white">
      <color rgba="1.0 1.0 1.0 1.0"/>
   </material>
   <material name="orange">
      <color rgba="1.0 0.4 0.0 1.0"/>
   </material>

   <material name="dr_gray">
      <color rgba="0.490 0.490 0.486 1.0"/>
   </material>
   <material name="dr_white">
      <color rgba="0.941 0.941 0.941 1.0"/>
   </material>

   <link name="base"/>
   <joint name="fixed" type="fixed">
      <parent link="base"/>
      <child link="base_0"/>
   </joint>
   <link name="base_0">
      <inertial>
         <mass value="1.803"/>
         <origin xyz="2.7e-05   -0.002651    0.035122"/>
         <inertia ixx="0.010608" ixy="1.7706e-06" ixz="6.6982e-06" iyy="0.0092656"
                  iyz="-4.7833e-05"
                  izz="0.0092125"/>
      </inertial>
      <visual>
         <origin rpy="0 0 0" xyz="0 0 0"/>
         <geometry>
            <mesh filename="package://meshes/E0509_0_0.dae"
                  scale="0.001 0.001 0.001"/>
         </geometry>
         <material name="dr_gray"/>
      </visual>
      <collision>
         <origin rpy="0 0 0" xyz="0 0 0"/>
         <geometry>
            <mesh filename="package://meshes/E0509_0_0.dae"
                  scale="0.001 0.001 0.001"/>
         </geometry>
      </collision>
   </link>
   <joint name="joint1" type="revolute">
      <parent link="base_0"/>
      <child link="link1"/>
      <origin rpy="0 0 0" xyz="0 0 0.2045"/>
      <axis xyz="0 0 1"/>
      <limit effort="194" lower="-6.2832" upper="6.2832" velocity="3.1416"/>
   </joint>
   <link name="link1">
      <inertial>
         <mass value="5.75"/>
         <origin xyz="1e-06    0.049633   -0.049635"/>
         <inertia ixx="0.046214" ixy="1.4982e-05" ixz="1.281e-05" iyy="0.032573" iyz="-0.013997"
                  izz="0.030999"/>
      </inertial>
      <visual>
         <origin rpy="0 0 0" xyz="0 0 0"/>
         <geometry>
            <mesh filename="package://meshes/E0509_1_1.dae"
                  scale="0.001 0.001 0.001"/>
         </geometry>
         <material name="dr_white"/>
      </visual>
      <collision>
         <origin rpy="0 0 0" xyz="0 0 0"/>
         <geometry>
            <mesh filename="package://meshes/E0509_1_1.dae"
                  scale="0.001 0.001 0.001"/>
         </geometry>
      </collision>
      <visual>
         <origin rpy="0 0 0" xyz="0 0 0"/>
         <geometry>
            <mesh filename="package://meshes/E0509_1_2.dae"
                  scale="0.001 0.001 0.001"/>
         </geometry>
         <material name="dr_white"/>
      </visual>
      <collision>
         <origin rpy="0 0 0" xyz="0 0 0"/>
         <geometry>
            <mesh filename="package://meshes/E0509_1_2.dae"
                  scale="0.001 0.001 0.001"/>
         </geometry>
      </collision>
      <visual>
         <origin rpy="0 0 0" xyz="0 0 0"/>
         <geometry>
            <mesh filename="package://meshes/E0509_1_3.dae"
                  scale="0.001 0.001 0.001"/>
         </geometry>
         <material name="dr_white"/>
      </visual>
      <collision>
         <origin rpy="0 0 0" xyz="0 0 0"/>
         <geometry>
            <mesh filename="package://meshes/E0509_1_3.dae"
                  scale="0.001 0.001 0.001"/>
         </geometry>
      </collision>
      <visual>
         <origin rpy="0 0 0" xyz="0 0 0"/>
         <geometry>
            <mesh filename="package://meshes/E0509_1_4.dae"
                  scale="0.001 0.001 0.001"/>
         </geometry>
         <material name="dr_white"/>
      </visual>
      <collision>
         <origin rpy="0 0 0" xyz="0 0 0"/>
         <geometry>
            <mesh filename="package://meshes/E0509_1_4.dae"
                  scale="0.001 0.001 0.001"/>
         </geometry>
      </collision>
   </link>
   <joint name="joint2" type="revolute">
      <parent link="link1"/>
      <child link="link2"/>
      <origin rpy="0     -1.5708     -1.5708" xyz="0  0  0"/>
      <axis xyz="0 0 1"/>
      <limit effort="194" lower="-6.2832" upper="6.2832" velocity="3.1416"/>
   </joint>
   <link name="link2">
      <inertial>
         <mass value="3.461"/>
         <origin xyz="0.18647 -1.1418e-17     0.17311"/>
         <inertia ixx="0.012039" ixy="7.7771e-06" ixz="3.7559e-06" iyy="0.091203"
                  iyz="3.1825e-06"
                  izz="0.094721"/>
      </inertial>
      <visual>
         <origin rpy="0 0 0" xyz="0 0 0"/>
         <geometry>
            <mesh filename="package://meshes/E0509_2_1.dae"
                  scale="0.001 0.001 0.001"/>
         </geometry>
         <material name="dr_white"/>
      </visual>
      <collision>
         <origin rpy="0 0 0" xyz="0 0 0"/>
         <geometry>
            <mesh filename="package://meshes/E0509_2_1.dae"
                  scale="0.001 0.001 0.001"/>
         </geometry>
      </collision>
      <visual>
         <origin rpy="0 0 0" xyz="0 0 0"/>
         <geometry>
            <mesh filename="package://meshes/E0509_2_2.dae"
                  scale="0.001 0.001 0.001"/>
         </geometry>
         <material name="dr_white"/>
      </visual>
      <collision>
         <origin rpy="0 0 0" xyz="0 0 0"/>
         <geometry>
            <mesh filename="package://meshes/E0509_2_2.dae"
                  scale="0.001 0.001 0.001"/>
         </geometry>
      </collision>
   </link>
   <joint name="joint3" type="revolute">
      <parent link="link2"/>
      <child link="link3"/>
      <origin rpy="0           0      1.5708" xyz="0.373           0           0"/>
      <axis xyz="0 0 1"/>
      <limit effort="194" lower="-2.7053" upper="2.7053" velocity="3.1416"/>
   </joint>
   <link name="link3">
      <inertial>
         <mass value="4.582"/>
         <origin xyz="1.2e-05    -0.02919    0.062355"/>
         <inertia ixx="0.032606" ixy="6.548e-06" ixz="-6.9939e-07" iyy="0.024211"
                  iyz="-0.0079929"
                  izz="0.019284"/>
      </inertial>
      <visual>
         <origin rpy="0 0 0" xyz="0 0 0"/>
         <geometry>
            <mesh filename="package://meshes/E0509_3_1.dae"
                  scale="0.001 0.001 0.001"/>
         </geometry>
         <material name="dr_white"/>
      </visual>
      <collision>
         <origin rpy="0 0 0" xyz="0 0 0"/>
         <geometry>
            <mesh filename="package://meshes/E0509_3_1.dae"
                  scale="0.001 0.001 0.001"/>
         </geometry>
      </collision>
      <visual>
         <origin rpy="0 0 0" xyz="0 0 0"/>
         <geometry>
            <mesh filename="package://meshes/E0509_3_2.dae"
                  scale="0.001 0.001 0.001"/>
         </geometry>
         <material name="dr_white"/>
      </visual>
      <collision>
         <origin rpy="0 0 0" xyz="0 0 0"/>
         <geometry>
            <mesh filename="package://meshes/E0509_3_2.dae"
                  scale="0.001 0.001 0.001"/>
         </geometry>
      </collision>
   </link>
   <joint name="joint4" type="revolute">
      <parent link="link3"/>
      <child link="link4"/>
      <origin rpy="1.5708           0           0" xyz="0      -0.373           0"/>
      <axis xyz="0 0 1"/>
      <limit effort="66" lower="-6.2832" upper="6.2832" velocity="3.927"/>
   </joint>
   <link name="link4">
      <inertial>
         <mass value="2.207"/>
         <origin xyz="4e-06    0.095573    -0.12813"/>
         <inertia ixx="0.03547" ixy="8.0794e-06" ixz="7.9905e-06" iyy="0.030841" iyz="-0.011996"
                  izz="0.019615"/>
      </inertial>
      <visual>
         <origin rpy="0 0 0" xyz="0 0 0"/>
         <geometry>
            <mesh filename="package://meshes/E0509_4_1.dae"
                  scale="0.001 0.001 0.001"/>
         </geometry>
         <material name="dr_white"/>
      </visual>
      <collision>
         <origin rpy="0 0 0" xyz="0 0 0"/>
         <geometry>
            <mesh filename="package://meshes/E0509_4_1.dae"
                  scale="0.001 0.001 0.001"/>
         </geometry>
         <material name="dr_white"/>
      </collision>
      <visual>
         <origin rpy="0 0 0" xyz="0 0 0"/>
         <geometry>
            <mesh filename="package://meshes/E0509_4_2.dae"
                  scale="0.001 0.001 0.001"/>
         </geometry>
         <material name="dr_white"/>
      </visual>
      <collision>
         <origin rpy="0 0 0" xyz="0 0 0"/>
         <geometry>
            <mesh filename="package://meshes/E0509_4_2.dae"
                  scale="0.001 0.001 0.001"/>
         </geometry>
      </collision>
   </link>
   <joint name="joint5" type="revolute">
      <parent link="link4"/>
      <child link="link5"/>
      <origin rpy="-1.5708           0           0" xyz="0  0  0"/>
      <axis xyz="0 0 1"/>
      <limit effort="66" lower="-6.2832" upper="6.2832" velocity="3.927"/>
   </joint>
   <link name="link5">
      <inertial>
         <mass value="3.545"/>
         <origin xyz="-3e-06   -0.038009    0.043841"/>
         <inertia ixx="0.023526" ixy="9.9368e-06" ixz="7.6673e-06" iyy="0.018415"
                  iyz="-0.0059939"
                  izz="0.014249"/>
      </inertial>
      <visual>
         <origin rpy="0 0 0" xyz="0 0 0"/>
         <geometry>
            <mesh filename="package://meshes/E0509_5_1.dae"
                  scale="0.001 0.001 0.001"/>
         </geometry>
         <material name="dr_white"/>
      </visual>
      <collision>
         <origin rpy="0 0 0" xyz="0 0 0"/>
         <geometry>
            <mesh filename="package://meshes/E0509_5_1.dae"
                  scale="0.001 0.001 0.001"/>
         </geometry>
         <material name="dr_white"/>
      </collision>
      <visual>
         <origin rpy="0 0 0" xyz="0 0 0"/>
         <geometry>
            <mesh filename="package://meshes/E0509_5_2.dae"
                  scale="0.001 0.001 0.001"/>
         </geometry>
         <material name="dr_white"/>
      </visual>
      <collision>
         <origin rpy="0 0 0" xyz="0 0 0"/>
         <geometry>
            <mesh filename="package://meshes/E0509_5_2.dae"
                  scale="0.001 0.001 0.001"/>
         </geometry>
      </collision>
   </link>
   <joint name="joint6" type="revolute">
      <parent link="link5"/>
      <child link="link6"/>
      <origin rpy="1.5708           0           0" xyz="0     -0.1725           0"/>
      <axis xyz="0 0 1"/>
      <limit effort="66" lower="-6.2832" upper="6.2832" velocity="3.927"/>
   </joint>
   <link name="link6">
      <inertial>
         <mass value="0.721"/>
         <origin xyz="5.4e-05   -0.000114   -0.032091"/>
         <inertia ixx="0.0048272" ixy="5.6302e-06" ixz="5.5274e-06" iyy="0.0046772"
                  iyz="3.9598e-06"
                  izz="0.0079424"/>
      </inertial>
      <visual>
         <origin rpy="0 0 0" xyz="0 0 0"/>
         <geometry>
            <mesh filename="package://meshes/E0509_6_1.dae"
                  scale="0.001 0.001 0.001"/>
         </geometry>
         <material name="dr_gray"/>
      </visual>
      <collision>
         <origin rpy="0 0 0" xyz="0 0 0"/>
         <geometry>
            <mesh filename="package://meshes/E0509_6_1.dae"
                  scale="0.001 0.001 0.001"/>
         </geometry>
      </collision>
   </link>

  <joint name="panda_hand_joint" type="fixed">
    <parent link="link6"/>
    <child link="panda_hand"/>
    <origin rpy="0 0 -0.785398163397" xyz="0 0 0"/>
  </joint>

  <link name="panda_hand">
  	<inertial>
      <origin rpy="0 0 0" xyz="0 0 0.04"/>
       <mass value=".81"/>
       <inertia ixx="0.1" ixy="0" ixz="0" iyy="0.1" iyz="0" izz="0.1"/>
    </inertial>
    <visual>
      <geometry>
        <mesh filename="package://meshes/panda/visual/hand.obj"/>
      </geometry>
      <material name="panda_white"/>
    </visual>
    <collision>
      <geometry>
        <mesh filename="package://meshes/panda/collision/hand.obj"/>
      </geometry>
      <material name="panda_white"/>
    </collision>
  </link>
  <link name="panda_leftfinger">
       <contact>
      <friction_anchor/>
      <stiffness value="30000.0"/>
      <damping value="1000.0"/>
      <spinning_friction value="0.1"/>
      <lateral_friction value="1.0"/>
    </contact>
  	<inertial>
      <origin rpy="0 0 0" xyz="0 0.01 0.02"/>
       <mass value="0.1"/>
       <inertia ixx="0.1" ixy="0" ixz="0" iyy="0.1" iyz="0" izz="0.1"/>
    </inertial>
    <visual>
      <geometry>
        <mesh filename="package://meshes/panda/visual/finger.obj"/>
      </geometry>
      <material name="panda_white"/>
    </visual>
    <collision>
      <geometry>
        <mesh filename="package://meshes/panda/collision/finger.obj"/>
      </geometry>
      <material name="panda_white"/>
    </collision>
  </link>
  <link name="panda_rightfinger">
    <contact>
      <friction_anchor/>
      <stiffness value="30000.0"/>
      <damping value="1000.0"/>
      <spinning_friction value="0.1"/>
      <lateral_friction value="1.0"/>
    </contact>

  	<inertial>
      <origin rpy="0 0 0" xyz="0 -0.01 0.02"/>
       <mass value="0.1"/>
       <inertia ixx="0.1" ixy="0" ixz="0" iyy="0.1" iyz="0" izz="0.1"/>
    </inertial>
    <visual>
      <origin rpy="0 0 3.14159265359" xyz="0 0 0"/>
      <geometry>
        <mesh filename="package://meshes/panda/visual/finger.obj"/>
      </geometry>
      <material name="panda_white"/>
    </visual>
    <collision>
      <origin rpy="0 0 3.14159265359" xyz="0 0 0"/>
      <geometry>
        <mesh filename="package://meshes/panda/collision/finger.obj"/>
      </geometry>
      <material name="panda_white"/>
    </collision>
  </link>

  <joint name="panda_finger_joint1" type="prismatic">
    <parent link="panda_hand"/>
    <child link="panda_leftfinger"/>
    <origin rpy="0 0 0" xyz="0 0 0.0584"/>
    <axis xyz="0 1 0"/>
    <limit effort="20" lower="0.0" upper="0.04" velocity="0.2"/>
  </joint>

  <joint name="panda_finger_joint2" type="prismatic">
    <parent link="panda_hand"/>
    <child link="panda_rightfinger"/>
    <origin rpy="0 0 0" xyz="0 0 0.0584"/>
    <axis xyz="0 -1 0"/>
    <limit effort="20" lower="0.0" upper="0.04" velocity="0.2"/>
    <mimic joint="panda_finger_joint1"/>
  </joint>

  <link name="panda_grasptarget">
    <inertial>
      <origin rpy="0 0 0" xyz="0 0 0"/>
      <mass value="0.0"/>
      <inertia ixx="0.1" ixy="0" ixz="0" iyy="0.1" iyz="0" izz="0.1"/>
    </inertial>
  </link>

  <joint name="panda_grasptarget_hand" type="fixed">
    <parent link="panda_hand"/>
    <child link="panda_grasptarget"/>
    <origin rpy="0 0 0" xyz="0 0 0.105"/>
  </joint>
</robot>